<?xml version="1.0" encoding="utf-8"?>
<robot xmlns:xacro="http://www.ros.org/wiki/xacro">
  <!--Auto-converted from finger1.xml
Grammar: grammar1=none, grammar2=none; counts: g1=1, g2=1
Δg1=(0.0, 0.0, 0.0), Δg2=(0.0, 0.0, 0.0)
Offsets: δ_middle=(0.0, 0.0, 0.0), δ_end=(0.0, 0.0, 0.0); flatten=False
Ghost joints: base=False, middle=False, end=False-->
  <xacro:macro name="finger1" params="prefix parent *origin">
    <link name="${prefix}finger_root">
      <inertial>
        <mass value="0.001"/>
        <inertia ixx="0.000001" ixy="0" ixz="0" iyy="0.000001" iyz="0" izz="0.000001"/>
      </inertial>
    </link>
    <joint name="${prefix}root_joint" type="fixed">
      <parent link="${parent}"/>
      <child link="${prefix}finger_root"/>
      <xacro:insert_block name="origin"/>
    </joint>
    <link name="${prefix}finger_palm_servo">
      <visual>
        <geometry>
          <mesh filename="robot_meshes/visual/finger_palm_servo_vis.obj"/>
        </geometry>
      </visual>
      <collision>
        <geometry>
          <mesh filename="robot_meshes/finger_palm_servo_part0.obj"/>
        </geometry>
      </collision>
      <inertial>
        <mass value="0.01"/>
        <inertia ixx="0.00001" ixy="0" ixz="0" iyy="0.00001" iyz="0" izz="0.00001"/>
      </inertial>
    </link>
    <joint name="${prefix}palm_servo_joint" type="fixed">
      <parent link="${prefix}finger_root"/>
      <child link="${prefix}finger_palm_servo"/>
      <origin xyz="0.00000 0.00000 0.00000" rpy="0 0 0"/>
    </joint>
    <link name="${prefix}finger_base">
      <visual>
        <origin xyz="0.01210 -0.07583 -0.03747" rpy="0 0 0"/>
        <geometry>
          <mesh filename="robot_meshes/visual/finger_base_vis.obj"/>
        </geometry>
      </visual>
      <collision>
        <origin xyz="0.01210 -0.07583 -0.03747" rpy="0 0 0"/>
        <geometry>
          <mesh filename="robot_meshes/finger_base_servo_part0.obj"/>
        </geometry>
      </collision>
      <inertial>
        <mass value="0.01"/>
        <inertia ixx="0.00001" ixy="0" ixz="0" iyy="0.00001" iyz="0" izz="0.00001"/>
      </inertial>
    </link>
    <joint name="${prefix}finger_palm_joint" type="revolute">
      <parent link="${prefix}finger_palm_servo"/>
      <child link="${prefix}finger_base"/>
      <origin xyz="-0.01210 0.07583 0.03747" rpy="0 0 0"/>
      <axis xyz="0.00000 0.00000 1.00000"/>
      <limit lower="-0.698" upper="0.698" effort="10" velocity="1.0"/>
      <dynamics damping="1.0"/>
    </joint>
    <link name="${prefix}finger_base_lever">
      <visual>
        <origin xyz="0.00032 -0.07716 -0.00489" rpy="0 0 0"/>
        <geometry>
          <mesh filename="robot_meshes/visual/finger_base_lever_vis.obj"/>
        </geometry>
      </visual>
      <collision>
        <origin xyz="0.00032 -0.07716 -0.00489" rpy="0 0 0"/>
        <geometry>
          <mesh filename="robot_meshes/finger_base_lever_part0.obj"/>
        </geometry>
      </collision>
      <collision>
        <origin xyz="0.00032 -0.07716 -0.00489" rpy="0 0 0"/>
        <geometry>
          <mesh filename="robot_meshes/finger_base_lever_part1.obj"/>
        </geometry>
      </collision>
      <collision>
        <origin xyz="0.00032 -0.07716 -0.00489" rpy="0 0 0"/>
        <geometry>
          <mesh filename="robot_meshes/finger_base_lever_part2.obj"/>
        </geometry>
      </collision>
      <visual>
        <origin xyz="0.00032 -0.07716 -0.00489" rpy="0 0 0"/>
        <geometry>
          <mesh filename="robot_meshes/visual/finger_grammar1_vis.obj"/>
        </geometry>
      </visual>
      <collision>
        <origin xyz="0.00032 -0.07716 -0.00489" rpy="0 0 0"/>
        <geometry>
          <mesh filename="robot_meshes/finger_grammar1_part0.obj"/>
        </geometry>
      </collision>
      <inertial>
        <mass value="0.01500"/>
        <inertia ixx="0.00001500" ixy="0" ixz="0" iyy="0.00001500" iyz="0" izz="0.00001500"/>
      </inertial>
    </link>
    <joint name="${prefix}finger_base_joint" type="revolute">
      <parent link="${prefix}finger_base"/>
      <child link="${prefix}finger_base_lever"/>
      <origin xyz="0.01178 0.00133 -0.03258" rpy="0 0 0"/>
      <axis xyz="-0.99238 -0.12319 0.00000"/>
      <limit lower="0.0" upper="1.5708" effort="10" velocity="1.0"/>
      <dynamics damping="1.0"/>
    </joint>
    <link name="${prefix}finger_middle">
      <visual>
        <origin xyz="0.00032 -0.07716 -0.00489" rpy="0 0 0"/>
        <geometry>
          <mesh filename="robot_meshes/visual/finger_middle_vis.obj"/>
        </geometry>
      </visual>
      <collision>
        <origin xyz="0.00032 -0.07716 -0.00489" rpy="0 0 0"/>
        <geometry>
          <mesh filename="robot_meshes/finger_middle_servo_part0.obj"/>
        </geometry>
      </collision>
      <inertial>
        <mass value="0.01"/>
        <inertia ixx="0.00001" ixy="0" ixz="0" iyy="0.00001" iyz="0" izz="0.00001"/>
      </inertial>
    </link>
    <joint name="${prefix}middle_joint" type="fixed">
      <parent link="${prefix}finger_base_lever"/>
      <child link="${prefix}finger_middle"/>
      <origin xyz="0.00000 0.00000 0.00000" rpy="0 0 0"/>
    </joint>
    <link name="${prefix}finger_middle_lever">
      <visual>
        <origin xyz="0.00696 -0.11319 -0.00376" rpy="0 0 0"/>
        <geometry>
          <mesh filename="robot_meshes/visual/finger_middle_lever_vis.obj"/>
        </geometry>
      </visual>
      <collision>
        <origin xyz="0.00696 -0.11319 -0.00376" rpy="0 0 0"/>
        <geometry>
          <mesh filename="robot_meshes/finger_middle_lever_part0.obj"/>
        </geometry>
      </collision>
      <collision>
        <origin xyz="0.00696 -0.11319 -0.00376" rpy="0 0 0"/>
        <geometry>
          <mesh filename="robot_meshes/finger_middle_lever_part1.obj"/>
        </geometry>
      </collision>
      <collision>
        <origin xyz="0.00696 -0.11319 -0.00376" rpy="0 0 0"/>
        <geometry>
          <mesh filename="robot_meshes/finger_middle_lever_part2.obj"/>
        </geometry>
      </collision>
      <visual>
        <origin xyz="0.00696 -0.11319 -0.00376" rpy="0 0 0"/>
        <geometry>
          <mesh filename="robot_meshes/visual/finger_grammar2_vis.obj"/>
        </geometry>
      </visual>
      <collision>
        <origin xyz="0.00696 -0.11319 -0.00376" rpy="0 0 0"/>
        <geometry>
          <mesh filename="robot_meshes/finger_grammar2_part0.obj"/>
        </geometry>
      </collision>
      <inertial>
        <mass value="0.01500"/>
        <inertia ixx="0.00001500" ixy="0" ixz="0" iyy="0.00001500" iyz="0" izz="0.00001500"/>
      </inertial>
    </link>
    <joint name="${prefix}finger_middle_joint" type="revolute">
      <parent link="${prefix}finger_middle"/>
      <child link="${prefix}finger_middle_lever"/>
      <origin xyz="-0.00664 0.03603 -0.00113" rpy="0 0 0"/>
      <axis xyz="-0.99236 -0.12337 0.00000"/>
      <limit lower="0.0" upper="1.5708" effort="10" velocity="1.0"/>
      <dynamics damping="1.0"/>
    </joint>
    <link name="${prefix}finger_end">
      <visual>
        <origin xyz="0.00696 -0.11319 -0.00376" rpy="0 0 0"/>
        <geometry>
          <mesh filename="robot_meshes/visual/finger_end_vis.obj"/>
        </geometry>
      </visual>
      <collision>
        <origin xyz="0.00696 -0.11319 -0.00376" rpy="0 0 0"/>
        <geometry>
          <mesh filename="robot_meshes/finger_end_servo_part0.obj"/>
        </geometry>
      </collision>
      <inertial>
        <mass value="0.01"/>
        <inertia ixx="0.00001" ixy="0" ixz="0" iyy="0.00001" iyz="0" izz="0.00001"/>
      </inertial>
    </link>
    <joint name="${prefix}end_joint" type="fixed">
      <parent link="${prefix}finger_middle_lever"/>
      <child link="${prefix}finger_end"/>
      <origin xyz="0.00000 0.00000 0.00000" rpy="0 0 0"/>
    </joint>
    <link name="${prefix}finger_end_lever">
      <visual>
        <origin xyz="0.00915 -0.14975 -0.00211" rpy="0 0 0"/>
        <geometry>
          <mesh filename="robot_meshes/visual/finger_end_lever_vis.obj"/>
        </geometry>
      </visual>
      <collision>
        <origin xyz="0.00915 -0.14975 -0.00211" rpy="0 0 0"/>
        <geometry>
          <mesh filename="robot_meshes/finger_end_lever_part0.obj"/>
        </geometry>
      </collision>
      <collision>
        <origin xyz="0.00915 -0.14975 -0.00211" rpy="0 0 0"/>
        <geometry>
          <mesh filename="robot_meshes/finger_end_lever_part1.obj"/>
        </geometry>
      </collision>
      <collision>
        <origin xyz="0.00915 -0.14975 -0.00211" rpy="0 0 0"/>
        <geometry>
          <mesh filename="robot_meshes/finger_end_lever_part2.obj"/>
        </geometry>
      </collision>
      <inertial>
        <mass value="0.01"/>
        <inertia ixx="0.00001" ixy="0" ixz="0" iyy="0.00001" iyz="0" izz="0.00001"/>
      </inertial>
    </link>
    <joint name="${prefix}finger_end_joint" type="revolute">
      <parent link="${prefix}finger_end"/>
      <child link="${prefix}finger_end_lever"/>
      <origin xyz="-0.00219 0.03656 -0.00165" rpy="0 0 0"/>
      <axis xyz="-0.99236 -0.12338 0.00000"/>
      <limit lower="0.0" upper="1.5708" effort="10" velocity="1.0"/>
      <dynamics damping="1.0"/>
    </joint>
    <link name="${prefix}finger_tip">
      <visual>
        <origin xyz="0.00915 -0.14975 -0.00211" rpy="0 0 0"/>
        <geometry>
          <mesh filename="robot_meshes/visual/finger_tip_thinner_vis.obj"/>
        </geometry>
      </visual>
      <collision>
        <origin xyz="0.00915 -0.14975 -0.00211" rpy="0 0 0"/>
        <geometry>
          <mesh filename="robot_meshes/finger_tip_thinner_part0.obj"/>
        </geometry>
      </collision>
      <collision>
        <origin xyz="0.00915 -0.14975 -0.00211" rpy="0 0 0"/>
        <geometry>
          <mesh filename="robot_meshes/finger_tip_thinner_part1.obj"/>
        </geometry>
      </collision>
      <inertial>
        <mass value="0.01"/>
        <inertia ixx="0.00001" ixy="0" ixz="0" iyy="0.00001" iyz="0" izz="0.00001"/>
      </inertial>
    </link>
    <joint name="${prefix}tip_joint" type="fixed">
      <parent link="${prefix}finger_end_lever"/>
      <child link="${prefix}finger_tip"/>
      <origin xyz="0.00000 0.00000 0.00000" rpy="0 0 0"/>
    </joint>
  </xacro:macro>
</robot>