<?xml version="1.0" ?>
<robot name="lego_hand">
  <link name="palm">
    <visual>
      <geometry>
        <mesh filename="robot_meshes/visual/palm_vis.obj"/>
      </geometry>
    </visual>
    <collision>
      <geometry>
        <mesh filename="robot_meshes/palm1_part0.obj"/>
      </geometry>
    </collision>
    <collision>
      <geometry>
        <mesh filename="robot_meshes/palm1_part1.obj"/>
      </geometry>
    </collision>
    <collision>
      <geometry>
        <mesh filename="robot_meshes/palm2_part0.obj"/>
      </geometry>
    </collision>
    <collision>
      <geometry>
        <mesh filename="robot_meshes/palm2_part1.obj"/>
      </geometry>
    </collision>
    <inertial>
      <mass value="0.1"/>
      <inertia ixx="0.001" ixy="0" ixz="0" iyy="0.001" iyz="0" izz="0.001"/>
    </inertial>
  </link>
  <link name="f1_finger_root">
    <inertial>
      <mass value="0.001"/>
      <inertia ixx="0.000001" ixy="0" ixz="0" iyy="0.000001" iyz="0" izz="0.000001"/>
    </inertial>
  </link>
  <joint name="f1_root_joint" type="fixed">
    <parent link="palm"/>
    <child link="f1_finger_root"/>
    <origin rpy="0.000000 0.000000 0.000000" xyz="0.000000 0.000000 0.000000"/>
  </joint>
  <link name="f1_finger_palm_servo">
    <visual>
      <geometry>
        <mesh filename="robot_meshes/visual/finger_palm_servo_vis.obj"/>
      </geometry>
    </visual>
    <collision>
      <geometry>
        <mesh filename="robot_meshes/finger_palm_servo_part0.obj"/>
      </geometry>
    </collision>
    <inertial>
      <mass value="0.01"/>
      <inertia ixx="0.00001" ixy="0" ixz="0" iyy="0.00001" iyz="0" izz="0.00001"/>
    </inertial>
  </link>
  <joint name="f1_palm_servo_joint" type="fixed">
    <parent link="f1_finger_root"/>
    <child link="f1_finger_palm_servo"/>
    <origin rpy="0.000000 0.000000 0.000000" xyz="0.000000 0.000000 0.000000"/>
  </joint>
  <link name="f1_finger_base">
    <visual>
      <origin rpy="0 0 0" xyz="-0.018630 -0.061720 0.028000"/>
      <geometry>
        <mesh filename="robot_meshes/visual/finger_base_vis.obj"/>
      </geometry>
    </visual>
    <collision>
      <origin rpy="0 0 0" xyz="-0.018630 -0.061720 0.028000"/>
      <geometry>
        <mesh filename="robot_meshes/finger_base_servo_part0.obj"/>
      </geometry>
    </collision>
    <inertial>
      <mass value="0.01"/>
      <inertia ixx="0.00001" ixy="0" ixz="0" iyy="0.00001" iyz="0" izz="0.00001"/>
    </inertial>
  </link>
  <joint name="f1_finger_palm_joint" type="revolute">
    <parent link="f1_finger_palm_servo"/>
    <child link="f1_finger_base"/>
    <origin rpy="0.000000 0.000000 0.000000" xyz="0.018630 0.061720 -0.028000"/>
    <axis xyz="0.000000 0.000000 1.000000"/>
    <limit effort="10.0" lower="-0.698000" upper="0.698000" velocity="1.0"/>
    <dynamics damping="0.1" friction="0.01"/>
  </joint>
  <link name="f1_finger_base_lever">
    <visual>
      <origin rpy="0 0 0" xyz="-0.035720 -0.062150 0.032640"/>
      <geometry>
        <mesh filename="robot_meshes/visual/finger_base_lever_vis.obj"/>
      </geometry>
    </visual>
    <collision>
      <origin rpy="0 0 0" xyz="-0.035720 -0.062150 0.032640"/>
      <geometry>
        <mesh filename="robot_meshes/finger_base_lever_part0.obj"/>
      </geometry>
    </collision>
    <collision>
      <origin rpy="0 0 0" xyz="-0.035720 -0.062150 0.032640"/>
      <geometry>
        <mesh filename="robot_meshes/finger_base_lever_part1.obj"/>
      </geometry>
    </collision>
    <collision>
      <origin rpy="0 0 0" xyz="-0.035720 -0.062150 0.032640"/>
      <geometry>
        <mesh filename="robot_meshes/finger_base_lever_part2.obj"/>
      </geometry>
    </collision>
    <visual>
      <origin rpy="0 0 0" xyz="-0.035720 -0.062150 0.032640"/>
      <geometry>
        <mesh filename="robot_meshes/visual/finger_grammar1_vis.obj"/>
      </geometry>
    </visual>
    <collision>
      <origin rpy="0 0 0" xyz="-0.035720 -0.062150 0.032640"/>
      <geometry>
        <mesh filename="robot_meshes/finger_grammar1_part0.obj"/>
      </geometry>
    </collision>
    <inertial>
      <mass value="0.015"/>
      <inertia ixx="0.000015" ixy="0" ixz="0" iyy="0.000015" iyz="0" izz="0.000015"/>
    </inertial>
  </link>
  <joint name="f1_finger_base_joint" type="revolute">
    <parent link="f1_finger_base"/>
    <child link="f1_finger_base_lever"/>
    <origin rpy="0.000000 0.000000 0.000000" xyz="0.017090 0.000430 -0.004640"/>
    <axis xyz="-0.999419 -0.034078 0.000000"/>
    <limit effort="10.0" lower="0.000000" upper="1.570800" velocity="1.0"/>
    <dynamics damping="0.1" friction="0.01"/>
  </joint>
  <link name="f1_finger_middle">
    <visual>
      <origin rpy="0 0 0" xyz="-0.035720 -0.062150 0.032640"/>
      <geometry>
        <mesh filename="robot_meshes/visual/finger_middle_vis.obj"/>
      </geometry>
    </visual>
    <collision>
      <origin rpy="0 0 0" xyz="-0.035720 -0.062150 0.032640"/>
      <geometry>
        <mesh filename="robot_meshes/finger_middle_servo_part0.obj"/>
      </geometry>
    </collision>
    <inertial>
      <mass value="0.01"/>
      <inertia ixx="0.00001" ixy="0" ixz="0" iyy="0.00001" iyz="0" izz="0.00001"/>
    </inertial>
  </link>
  <joint name="f1_middle_joint" type="fixed">
    <parent link="f1_finger_base_lever"/>
    <child link="f1_finger_middle"/>
    <origin rpy="0.000000 0.000000 0.000000" xyz="0.000000 0.000000 0.000000"/>
  </joint>
  <link name="f1_finger_middle_lever">
    <visual>
      <origin rpy="0 0 0" xyz="-0.034570 -0.093620 0.033780"/>
      <geometry>
        <mesh filename="robot_meshes/visual/finger_middle_lever_vis.obj"/>
      </geometry>
    </visual>
    <collision>
      <origin rpy="0 0 0" xyz="-0.034570 -0.093620 0.033780"/>
      <geometry>
        <mesh filename="robot_meshes/finger_middle_lever_part0.obj"/>
      </geometry>
    </collision>
    <collision>
      <origin rpy="0 0 0" xyz="-0.034570 -0.093620 0.033780"/>
      <geometry>
        <mesh filename="robot_meshes/finger_middle_lever_part1.obj"/>
      </geometry>
    </collision>
    <collision>
      <origin rpy="0 0 0" xyz="-0.034570 -0.093620 0.033780"/>
      <geometry>
        <mesh filename="robot_meshes/finger_middle_lever_part2.obj"/>
      </geometry>
    </collision>
    <visual>
      <origin rpy="0 0 0" xyz="-0.034570 -0.093620 0.033780"/>
      <geometry>
        <mesh filename="robot_meshes/visual/finger_grammar2_vis.obj"/>
      </geometry>
    </visual>
    <collision>
      <origin rpy="0 0 0" xyz="-0.034570 -0.093620 0.033780"/>
      <geometry>
        <mesh filename="robot_meshes/finger_grammar2_part0.obj"/>
      </geometry>
    </collision>
    <inertial>
      <mass value="0.015"/>
      <inertia ixx="0.000015" ixy="0" ixz="0" iyy="0.000015" iyz="0" izz="0.000015"/>
    </inertial>
  </link>
  <joint name="f1_finger_middle_joint" type="revolute">
    <parent link="f1_finger_middle"/>
    <child link="f1_finger_middle_lever"/>
    <origin rpy="0.000000 0.000000 0.000000" xyz="-0.001150 0.031470 -0.001140"/>
    <axis xyz="-0.999419 -0.034078 0.000000"/>
    <limit effort="10.0" lower="0.000000" upper="1.570800" velocity="1.0"/>
    <dynamics damping="0.1" friction="0.01"/>
  </joint>
  <link name="f1_finger_end">
    <visual>
      <origin rpy="0 0 0" xyz="-0.034570 -0.093620 0.033780"/>
      <geometry>
        <mesh filename="robot_meshes/visual/finger_end_vis.obj"/>
      </geometry>
    </visual>
    <collision>
      <origin rpy="0 0 0" xyz="-0.034570 -0.093620 0.033780"/>
      <geometry>
        <mesh filename="robot_meshes/finger_end_servo_part0.obj"/>
      </geometry>
    </collision>
    <inertial>
      <mass value="0.01"/>
      <inertia ixx="0.00001" ixy="0" ixz="0" iyy="0.00001" iyz="0" izz="0.00001"/>
    </inertial>
  </link>
  <joint name="f1_end_joint" type="fixed">
    <parent link="f1_finger_middle_lever"/>
    <child link="f1_finger_end"/>
    <origin rpy="0.000000 0.000000 0.000000" xyz="0.000000 0.000000 0.000000"/>
  </joint>
  <link name="f1_finger_end_lever">
    <visual>
      <origin rpy="0 0 0" xyz="-0.033530 -0.125100 0.034780"/>
      <geometry>
        <mesh filename="robot_meshes/visual/finger_end_lever_vis.obj"/>
      </geometry>
    </visual>
    <collision>
      <origin rpy="0 0 0" xyz="-0.033530 -0.125100 0.034780"/>
      <geometry>
        <mesh filename="robot_meshes/finger_end_lever_part0.obj"/>
      </geometry>
    </collision>
    <collision>
      <origin rpy="0 0 0" xyz="-0.033530 -0.125100 0.034780"/>
      <geometry>
        <mesh filename="robot_meshes/finger_end_lever_part1.obj"/>
      </geometry>
    </collision>
    <collision>
      <origin rpy="0 0 0" xyz="-0.033530 -0.125100 0.034780"/>
      <geometry>
        <mesh filename="robot_meshes/finger_end_lever_part2.obj"/>
      </geometry>
    </collision>
    <collision>
      <origin rpy="0 0 0" xyz="-0.033530 -0.125100 0.034780"/>
      <geometry>
        <mesh filename="robot_meshes/finger_end_lever_part3.obj"/>
      </geometry>
    </collision>
    <inertial>
      <mass value="0.01"/>
      <inertia ixx="0.00001" ixy="0" ixz="0" iyy="0.00001" iyz="0" izz="0.00001"/>
    </inertial>
  </link>
  <joint name="f1_finger_end_joint" type="revolute">
    <parent link="f1_finger_end"/>
    <child link="f1_finger_end_lever"/>
    <origin rpy="0.000000 0.000000 0.000000" xyz="-0.001040 0.031480 -0.001000"/>
    <axis xyz="-0.999419 -0.034088 0.000000"/>
    <limit effort="10.0" lower="0.000000" upper="1.570800" velocity="1.0"/>
    <dynamics damping="0.1" friction="0.01"/>
  </joint>
  <link name="f1_finger_tip">
    <visual>
      <origin rpy="0 0 0" xyz="-0.033530 -0.125100 0.034780"/>
      <geometry>
        <mesh filename="robot_meshes/visual/finger_tip_vis.obj"/>
      </geometry>
    </visual>
    <collision>
      <origin rpy="0 0 0" xyz="-0.033530 -0.125100 0.034780"/>
      <geometry>
        <mesh filename="robot_meshes/finger_tip_part0.obj"/>
      </geometry>
    </collision>
    <collision>
      <origin rpy="0 0 0" xyz="-0.033530 -0.125100 0.034780"/>
      <geometry>
        <mesh filename="robot_meshes/finger_tip_part1.obj"/>
      </geometry>
    </collision>
    <inertial>
      <mass value="0.005"/>
      <inertia ixx="0.000001" ixy="0" ixz="0" iyy="0.000001" iyz="0" izz="0.000001"/>
    </inertial>
  </link>
  <joint name="f1_tip_joint" type="fixed">
    <parent link="f1_finger_end_lever"/>
    <child link="f1_finger_tip"/>
    <origin rpy="0.000000 0.000000 0.000000" xyz="0.000000 0.000000 0.000000"/>
  </joint>
  <link name="f2_finger_root">
    <inertial>
      <mass value="0.001"/>
      <inertia ixx="0.000001" ixy="0" ixz="0" iyy="0.000001" iyz="0" izz="0.000001"/>
    </inertial>
  </link>
  <joint name="f2_root_joint" type="fixed">
    <parent link="palm"/>
    <child link="f2_finger_root"/>
    <origin rpy="0.000000 0.000000 -0.558867" xyz="0.025080 0.024835 0.000000"/>
  </joint>
  <link name="f2_finger_palm_servo">
    <visual>
      <geometry>
        <mesh filename="robot_meshes/visual/finger_palm_servo_vis.obj"/>
      </geometry>
    </visual>
    <collision>
      <geometry>
        <mesh filename="robot_meshes/finger_palm_servo_part0.obj"/>
      </geometry>
    </collision>
    <inertial>
      <mass value="0.01"/>
      <inertia ixx="0.00001" ixy="0" ixz="0" iyy="0.00001" iyz="0" izz="0.00001"/>
    </inertial>
  </link>
  <joint name="f2_palm_servo_joint" type="fixed">
    <parent link="f2_finger_root"/>
    <child link="f2_finger_palm_servo"/>
    <origin rpy="0.000000 0.000000 0.000000" xyz="0.000000 0.000000 0.000000"/>
  </joint>
  <link name="f2_finger_base">
    <visual>
      <origin rpy="0 0 0" xyz="-0.018630 -0.061720 0.028000"/>
      <geometry>
        <mesh filename="robot_meshes/visual/finger_base_vis.obj"/>
      </geometry>
    </visual>
    <collision>
      <origin rpy="0 0 0" xyz="-0.018630 -0.061720 0.028000"/>
      <geometry>
        <mesh filename="robot_meshes/finger_base_servo_part0.obj"/>
      </geometry>
    </collision>
    <inertial>
      <mass value="0.01"/>
      <inertia ixx="0.00001" ixy="0" ixz="0" iyy="0.00001" iyz="0" izz="0.00001"/>
    </inertial>
  </link>
  <joint name="f2_finger_palm_joint" type="revolute">
    <parent link="f2_finger_palm_servo"/>
    <child link="f2_finger_base"/>
    <origin rpy="0.000000 0.000000 0.000000" xyz="0.018630 0.061720 -0.028000"/>
    <axis xyz="0.000000 0.000000 1.000000"/>
    <limit effort="10.0" lower="-0.698000" upper="0.698000" velocity="1.0"/>
    <dynamics damping="0.1" friction="0.01"/>
  </joint>
  <link name="f2_finger_base_lever">
    <visual>
      <origin rpy="0 0 0" xyz="-0.035720 -0.062150 0.032640"/>
      <geometry>
        <mesh filename="robot_meshes/visual/finger_base_lever_vis.obj"/>
      </geometry>
    </visual>
    <collision>
      <origin rpy="0 0 0" xyz="-0.035720 -0.062150 0.032640"/>
      <geometry>
        <mesh filename="robot_meshes/finger_base_lever_part0.obj"/>
      </geometry>
    </collision>
    <collision>
      <origin rpy="0 0 0" xyz="-0.035720 -0.062150 0.032640"/>
      <geometry>
        <mesh filename="robot_meshes/finger_base_lever_part1.obj"/>
      </geometry>
    </collision>
    <collision>
      <origin rpy="0 0 0" xyz="-0.035720 -0.062150 0.032640"/>
      <geometry>
        <mesh filename="robot_meshes/finger_base_lever_part2.obj"/>
      </geometry>
    </collision>
    <visual>
      <origin rpy="0 0 0" xyz="-0.035720 -0.062150 0.032640"/>
      <geometry>
        <mesh filename="robot_meshes/visual/finger_grammar1_vis.obj"/>
      </geometry>
    </visual>
    <collision>
      <origin rpy="0 0 0" xyz="-0.035720 -0.062150 0.032640"/>
      <geometry>
        <mesh filename="robot_meshes/finger_grammar1_part0.obj"/>
      </geometry>
    </collision>
    <inertial>
      <mass value="0.015"/>
      <inertia ixx="0.000015" ixy="0" ixz="0" iyy="0.000015" iyz="0" izz="0.000015"/>
    </inertial>
  </link>
  <joint name="f2_finger_base_joint" type="revolute">
    <parent link="f2_finger_base"/>
    <child link="f2_finger_base_lever"/>
    <origin rpy="0.000000 0.000000 0.000000" xyz="0.017090 0.000430 -0.004640"/>
    <axis xyz="-0.999419 -0.034078 0.000000"/>
    <limit effort="10.0" lower="0.000000" upper="1.570800" velocity="1.0"/>
    <dynamics damping="0.1" friction="0.01"/>
  </joint>
  <link name="f2_finger_middle">
    <visual>
      <origin rpy="0 0 0" xyz="-0.035720 -0.062150 0.032640"/>
      <geometry>
        <mesh filename="robot_meshes/visual/finger_middle_vis.obj"/>
      </geometry>
    </visual>
    <collision>
      <origin rpy="0 0 0" xyz="-0.035720 -0.062150 0.032640"/>
      <geometry>
        <mesh filename="robot_meshes/finger_middle_servo_part0.obj"/>
      </geometry>
    </collision>
    <inertial>
      <mass value="0.01"/>
      <inertia ixx="0.00001" ixy="0" ixz="0" iyy="0.00001" iyz="0" izz="0.00001"/>
    </inertial>
  </link>
  <joint name="f2_middle_joint" type="fixed">
    <parent link="f2_finger_base_lever"/>
    <child link="f2_finger_middle"/>
    <origin rpy="0.000000 0.000000 0.000000" xyz="0.000000 0.000000 0.000000"/>
  </joint>
  <link name="f2_finger_middle_lever">
    <visual>
      <origin rpy="0 0 0" xyz="-0.034570 -0.093620 0.033780"/>
      <geometry>
        <mesh filename="robot_meshes/visual/finger_middle_lever_vis.obj"/>
      </geometry>
    </visual>
    <collision>
      <origin rpy="0 0 0" xyz="-0.034570 -0.093620 0.033780"/>
      <geometry>
        <mesh filename="robot_meshes/finger_middle_lever_part0.obj"/>
      </geometry>
    </collision>
    <collision>
      <origin rpy="0 0 0" xyz="-0.034570 -0.093620 0.033780"/>
      <geometry>
        <mesh filename="robot_meshes/finger_middle_lever_part1.obj"/>
      </geometry>
    </collision>
    <collision>
      <origin rpy="0 0 0" xyz="-0.034570 -0.093620 0.033780"/>
      <geometry>
        <mesh filename="robot_meshes/finger_middle_lever_part2.obj"/>
      </geometry>
    </collision>
    <visual>
      <origin rpy="0 0 0" xyz="-0.034570 -0.093620 0.033780"/>
      <geometry>
        <mesh filename="robot_meshes/visual/finger_grammar2_vis.obj"/>
      </geometry>
    </visual>
    <collision>
      <origin rpy="0 0 0" xyz="-0.034570 -0.093620 0.033780"/>
      <geometry>
        <mesh filename="robot_meshes/finger_grammar2_part0.obj"/>
      </geometry>
    </collision>
    <inertial>
      <mass value="0.015"/>
      <inertia ixx="0.000015" ixy="0" ixz="0" iyy="0.000015" iyz="0" izz="0.000015"/>
    </inertial>
  </link>
  <joint name="f2_finger_middle_joint" type="revolute">
    <parent link="f2_finger_middle"/>
    <child link="f2_finger_middle_lever"/>
    <origin rpy="0.000000 0.000000 0.000000" xyz="-0.001150 0.031470 -0.001140"/>
    <axis xyz="-0.999419 -0.034078 0.000000"/>
    <limit effort="10.0" lower="0.000000" upper="1.570800" velocity="1.0"/>
    <dynamics damping="0.1" friction="0.01"/>
  </joint>
  <link name="f2_finger_end">
    <visual>
      <origin rpy="0 0 0" xyz="-0.034570 -0.093620 0.033780"/>
      <geometry>
        <mesh filename="robot_meshes/visual/finger_end_vis.obj"/>
      </geometry>
    </visual>
    <collision>
      <origin rpy="0 0 0" xyz="-0.034570 -0.093620 0.033780"/>
      <geometry>
        <mesh filename="robot_meshes/finger_end_servo_part0.obj"/>
      </geometry>
    </collision>
    <inertial>
      <mass value="0.01"/>
      <inertia ixx="0.00001" ixy="0" ixz="0" iyy="0.00001" iyz="0" izz="0.00001"/>
    </inertial>
  </link>
  <joint name="f2_end_joint" type="fixed">
    <parent link="f2_finger_middle_lever"/>
    <child link="f2_finger_end"/>
    <origin rpy="0.000000 0.000000 0.000000" xyz="0.000000 0.000000 0.000000"/>
  </joint>
  <link name="f2_finger_end_lever">
    <visual>
      <origin rpy="0 0 0" xyz="-0.033530 -0.125100 0.034780"/>
      <geometry>
        <mesh filename="robot_meshes/visual/finger_end_lever_vis.obj"/>
      </geometry>
    </visual>
    <collision>
      <origin rpy="0 0 0" xyz="-0.033530 -0.125100 0.034780"/>
      <geometry>
        <mesh filename="robot_meshes/finger_end_lever_part0.obj"/>
      </geometry>
    </collision>
    <collision>
      <origin rpy="0 0 0" xyz="-0.033530 -0.125100 0.034780"/>
      <geometry>
        <mesh filename="robot_meshes/finger_end_lever_part1.obj"/>
      </geometry>
    </collision>
    <collision>
      <origin rpy="0 0 0" xyz="-0.033530 -0.125100 0.034780"/>
      <geometry>
        <mesh filename="robot_meshes/finger_end_lever_part2.obj"/>
      </geometry>
    </collision>
    <collision>
      <origin rpy="0 0 0" xyz="-0.033530 -0.125100 0.034780"/>
      <geometry>
        <mesh filename="robot_meshes/finger_end_lever_part3.obj"/>
      </geometry>
    </collision>
    <inertial>
      <mass value="0.01"/>
      <inertia ixx="0.00001" ixy="0" ixz="0" iyy="0.00001" iyz="0" izz="0.00001"/>
    </inertial>
  </link>
  <joint name="f2_finger_end_joint" type="revolute">
    <parent link="f2_finger_end"/>
    <child link="f2_finger_end_lever"/>
    <origin rpy="0.000000 0.000000 0.000000" xyz="-0.001040 0.031480 -0.001000"/>
    <axis xyz="-0.999419 -0.034088 0.000000"/>
    <limit effort="10.0" lower="0.000000" upper="1.570800" velocity="1.0"/>
    <dynamics damping="0.1" friction="0.01"/>
  </joint>
  <link name="f2_finger_tip">
    <visual>
      <origin rpy="0 0 0" xyz="-0.033530 -0.125100 0.034780"/>
      <geometry>
        <mesh filename="robot_meshes/visual/finger_tip_vis.obj"/>
      </geometry>
    </visual>
    <collision>
      <origin rpy="0 0 0" xyz="-0.033530 -0.125100 0.034780"/>
      <geometry>
        <mesh filename="robot_meshes/finger_tip_part0.obj"/>
      </geometry>
    </collision>
    <collision>
      <origin rpy="0 0 0" xyz="-0.033530 -0.125100 0.034780"/>
      <geometry>
        <mesh filename="robot_meshes/finger_tip_part1.obj"/>
      </geometry>
    </collision>
    <inertial>
      <mass value="0.005"/>
      <inertia ixx="0.000001" ixy="0" ixz="0" iyy="0.000001" iyz="0" izz="0.000001"/>
    </inertial>
  </link>
  <joint name="f2_tip_joint" type="fixed">
    <parent link="f2_finger_end_lever"/>
    <child link="f2_finger_tip"/>
    <origin rpy="0.000000 0.000000 0.000000" xyz="0.000000 0.000000 0.000000"/>
  </joint>
  <link name="f3_finger_root">
    <inertial>
      <mass value="0.001"/>
      <inertia ixx="0.000001" ixy="0" ixz="0" iyy="0.000001" iyz="0" izz="0.000001"/>
    </inertial>
  </link>
  <joint name="f3_root_joint" type="fixed">
    <parent link="palm"/>
    <child link="f3_finger_root"/>
    <origin rpy="0.000000 0.000000 -1.403303" xyz="0.041631 0.031106 0.000000"/>
  </joint>
  <link name="f3_finger_palm_servo">
    <visual>
      <geometry>
        <mesh filename="robot_meshes/visual/finger_palm_servo_vis.obj"/>
      </geometry>
    </visual>
    <collision>
      <geometry>
        <mesh filename="robot_meshes/finger_palm_servo_part0.obj"/>
      </geometry>
    </collision>
    <inertial>
      <mass value="0.01"/>
      <inertia ixx="0.00001" ixy="0" ixz="0" iyy="0.00001" iyz="0" izz="0.00001"/>
    </inertial>
  </link>
  <joint name="f3_palm_servo_joint" type="fixed">
    <parent link="f3_finger_root"/>
    <child link="f3_finger_palm_servo"/>
    <origin rpy="0.000000 0.000000 0.000000" xyz="0.000000 0.000000 0.000000"/>
  </joint>
  <link name="f3_finger_base">
    <visual>
      <origin rpy="0 0 0" xyz="-0.018630 -0.061720 0.028000"/>
      <geometry>
        <mesh filename="robot_meshes/visual/finger_base_vis.obj"/>
      </geometry>
    </visual>
    <collision>
      <origin rpy="0 0 0" xyz="-0.018630 -0.061720 0.028000"/>
      <geometry>
        <mesh filename="robot_meshes/finger_base_servo_part0.obj"/>
      </geometry>
    </collision>
    <inertial>
      <mass value="0.01"/>
      <inertia ixx="0.00001" ixy="0" ixz="0" iyy="0.00001" iyz="0" izz="0.00001"/>
    </inertial>
  </link>
  <joint name="f3_finger_palm_joint" type="revolute">
    <parent link="f3_finger_palm_servo"/>
    <child link="f3_finger_base"/>
    <origin rpy="0.000000 0.000000 0.000000" xyz="0.018630 0.061720 -0.028000"/>
    <axis xyz="0.000000 0.000000 1.000000"/>
    <limit effort="10.0" lower="-0.698000" upper="0.698000" velocity="1.0"/>
    <dynamics damping="0.1" friction="0.01"/>
  </joint>
  <link name="f3_finger_base_lever">
    <visual>
      <origin rpy="0 0 0" xyz="-0.035720 -0.062150 0.032640"/>
      <geometry>
        <mesh filename="robot_meshes/visual/finger_base_lever_vis.obj"/>
      </geometry>
    </visual>
    <collision>
      <origin rpy="0 0 0" xyz="-0.035720 -0.062150 0.032640"/>
      <geometry>
        <mesh filename="robot_meshes/finger_base_lever_part0.obj"/>
      </geometry>
    </collision>
    <collision>
      <origin rpy="0 0 0" xyz="-0.035720 -0.062150 0.032640"/>
      <geometry>
        <mesh filename="robot_meshes/finger_base_lever_part1.obj"/>
      </geometry>
    </collision>
    <collision>
      <origin rpy="0 0 0" xyz="-0.035720 -0.062150 0.032640"/>
      <geometry>
        <mesh filename="robot_meshes/finger_base_lever_part2.obj"/>
      </geometry>
    </collision>
    <visual>
      <origin rpy="0 0 0" xyz="-0.035720 -0.062150 0.032640"/>
      <geometry>
        <mesh filename="robot_meshes/visual/finger_grammar1_vis.obj"/>
      </geometry>
    </visual>
    <collision>
      <origin rpy="0 0 0" xyz="-0.035720 -0.062150 0.032640"/>
      <geometry>
        <mesh filename="robot_meshes/finger_grammar1_part0.obj"/>
      </geometry>
    </collision>
    <inertial>
      <mass value="0.015"/>
      <inertia ixx="0.000015" ixy="0" ixz="0" iyy="0.000015" iyz="0" izz="0.000015"/>
    </inertial>
  </link>
  <joint name="f3_finger_base_joint" type="revolute">
    <parent link="f3_finger_base"/>
    <child link="f3_finger_base_lever"/>
    <origin rpy="0.000000 0.000000 0.000000" xyz="0.017090 0.000430 -0.004640"/>
    <axis xyz="-0.999419 -0.034078 0.000000"/>
    <limit effort="10.0" lower="0.000000" upper="1.570800" velocity="1.0"/>
    <dynamics damping="0.1" friction="0.01"/>
  </joint>
  <link name="f3_finger_middle">
    <visual>
      <origin rpy="0 0 0" xyz="-0.035720 -0.062150 0.032640"/>
      <geometry>
        <mesh filename="robot_meshes/visual/finger_middle_vis.obj"/>
      </geometry>
    </visual>
    <collision>
      <origin rpy="0 0 0" xyz="-0.035720 -0.062150 0.032640"/>
      <geometry>
        <mesh filename="robot_meshes/finger_middle_servo_part0.obj"/>
      </geometry>
    </collision>
    <inertial>
      <mass value="0.01"/>
      <inertia ixx="0.00001" ixy="0" ixz="0" iyy="0.00001" iyz="0" izz="0.00001"/>
    </inertial>
  </link>
  <joint name="f3_middle_joint" type="fixed">
    <parent link="f3_finger_base_lever"/>
    <child link="f3_finger_middle"/>
    <origin rpy="0.000000 0.000000 0.000000" xyz="0.000000 0.000000 0.000000"/>
  </joint>
  <link name="f3_finger_middle_lever">
    <visual>
      <origin rpy="0 0 0" xyz="-0.034570 -0.093620 0.033780"/>
      <geometry>
        <mesh filename="robot_meshes/visual/finger_middle_lever_vis.obj"/>
      </geometry>
    </visual>
    <collision>
      <origin rpy="0 0 0" xyz="-0.034570 -0.093620 0.033780"/>
      <geometry>
        <mesh filename="robot_meshes/finger_middle_lever_part0.obj"/>
      </geometry>
    </collision>
    <collision>
      <origin rpy="0 0 0" xyz="-0.034570 -0.093620 0.033780"/>
      <geometry>
        <mesh filename="robot_meshes/finger_middle_lever_part1.obj"/>
      </geometry>
    </collision>
    <collision>
      <origin rpy="0 0 0" xyz="-0.034570 -0.093620 0.033780"/>
      <geometry>
        <mesh filename="robot_meshes/finger_middle_lever_part2.obj"/>
      </geometry>
    </collision>
    <visual>
      <origin rpy="0 0 0" xyz="-0.034570 -0.093620 0.033780"/>
      <geometry>
        <mesh filename="robot_meshes/visual/finger_grammar2_vis.obj"/>
      </geometry>
    </visual>
    <collision>
      <origin rpy="0 0 0" xyz="-0.034570 -0.093620 0.033780"/>
      <geometry>
        <mesh filename="robot_meshes/finger_grammar2_part0.obj"/>
      </geometry>
    </collision>
    <inertial>
      <mass value="0.015"/>
      <inertia ixx="0.000015" ixy="0" ixz="0" iyy="0.000015" iyz="0" izz="0.000015"/>
    </inertial>
  </link>
  <joint name="f3_finger_middle_joint" type="revolute">
    <parent link="f3_finger_middle"/>
    <child link="f3_finger_middle_lever"/>
    <origin rpy="0.000000 0.000000 0.000000" xyz="-0.001150 0.031470 -0.001140"/>
    <axis xyz="-0.999419 -0.034078 0.000000"/>
    <limit effort="10.0" lower="0.000000" upper="1.570800" velocity="1.0"/>
    <dynamics damping="0.1" friction="0.01"/>
  </joint>
  <link name="f3_finger_end">
    <visual>
      <origin rpy="0 0 0" xyz="-0.034570 -0.093620 0.033780"/>
      <geometry>
        <mesh filename="robot_meshes/visual/finger_end_vis.obj"/>
      </geometry>
    </visual>
    <collision>
      <origin rpy="0 0 0" xyz="-0.034570 -0.093620 0.033780"/>
      <geometry>
        <mesh filename="robot_meshes/finger_end_servo_part0.obj"/>
      </geometry>
    </collision>
    <inertial>
      <mass value="0.01"/>
      <inertia ixx="0.00001" ixy="0" ixz="0" iyy="0.00001" iyz="0" izz="0.00001"/>
    </inertial>
  </link>
  <joint name="f3_end_joint" type="fixed">
    <parent link="f3_finger_middle_lever"/>
    <child link="f3_finger_end"/>
    <origin rpy="0.000000 0.000000 0.000000" xyz="0.000000 0.000000 0.000000"/>
  </joint>
  <link name="f3_finger_end_lever">
    <visual>
      <origin rpy="0 0 0" xyz="-0.033530 -0.125100 0.034780"/>
      <geometry>
        <mesh filename="robot_meshes/visual/finger_end_lever_vis.obj"/>
      </geometry>
    </visual>
    <collision>
      <origin rpy="0 0 0" xyz="-0.033530 -0.125100 0.034780"/>
      <geometry>
        <mesh filename="robot_meshes/finger_end_lever_part0.obj"/>
      </geometry>
    </collision>
    <collision>
      <origin rpy="0 0 0" xyz="-0.033530 -0.125100 0.034780"/>
      <geometry>
        <mesh filename="robot_meshes/finger_end_lever_part1.obj"/>
      </geometry>
    </collision>
    <collision>
      <origin rpy="0 0 0" xyz="-0.033530 -0.125100 0.034780"/>
      <geometry>
        <mesh filename="robot_meshes/finger_end_lever_part2.obj"/>
      </geometry>
    </collision>
    <collision>
      <origin rpy="0 0 0" xyz="-0.033530 -0.125100 0.034780"/>
      <geometry>
        <mesh filename="robot_meshes/finger_end_lever_part3.obj"/>
      </geometry>
    </collision>
    <inertial>
      <mass value="0.01"/>
      <inertia ixx="0.00001" ixy="0" ixz="0" iyy="0.00001" iyz="0" izz="0.00001"/>
    </inertial>
  </link>
  <joint name="f3_finger_end_joint" type="revolute">
    <parent link="f3_finger_end"/>
    <child link="f3_finger_end_lever"/>
    <origin rpy="0.000000 0.000000 0.000000" xyz="-0.001040 0.031480 -0.001000"/>
    <axis xyz="-0.999419 -0.034088 0.000000"/>
    <limit effort="10.0" lower="0.000000" upper="1.570800" velocity="1.0"/>
    <dynamics damping="0.1" friction="0.01"/>
  </joint>
  <link name="f3_finger_tip">
    <visual>
      <origin rpy="0 0 0" xyz="-0.033530 -0.125100 0.034780"/>
      <geometry>
        <mesh filename="robot_meshes/visual/finger_tip_vis.obj"/>
      </geometry>
    </visual>
    <collision>
      <origin rpy="0 0 0" xyz="-0.033530 -0.125100 0.034780"/>
      <geometry>
        <mesh filename="robot_meshes/finger_tip_part0.obj"/>
      </geometry>
    </collision>
    <collision>
      <origin rpy="0 0 0" xyz="-0.033530 -0.125100 0.034780"/>
      <geometry>
        <mesh filename="robot_meshes/finger_tip_part1.obj"/>
      </geometry>
    </collision>
    <inertial>
      <mass value="0.005"/>
      <inertia ixx="0.000001" ixy="0" ixz="0" iyy="0.000001" iyz="0" izz="0.000001"/>
    </inertial>
  </link>
  <joint name="f3_tip_joint" type="fixed">
    <parent link="f3_finger_end_lever"/>
    <child link="f3_finger_tip"/>
    <origin rpy="0.000000 0.000000 0.000000" xyz="0.000000 0.000000 0.000000"/>
  </joint>
  <link name="f4_finger_root">
    <inertial>
      <mass value="0.001"/>
      <inertia ixx="0.000001" ixy="0" ixz="0" iyy="0.000001" iyz="0" izz="0.000001"/>
    </inertial>
  </link>
  <joint name="f4_root_joint" type="fixed">
    <parent link="palm"/>
    <child link="f4_finger_root"/>
    <origin rpy="0.000000 0.000000 -1.907016" xyz="0.052468 0.010662 0.000000"/>
  </joint>
  <link name="f4_finger_palm_servo">
    <visual>
      <geometry>
        <mesh filename="robot_meshes/visual/finger_palm_servo_vis.obj"/>
      </geometry>
    </visual>
    <collision>
      <geometry>
        <mesh filename="robot_meshes/finger_palm_servo_part0.obj"/>
      </geometry>
    </collision>
    <inertial>
      <mass value="0.01"/>
      <inertia ixx="0.00001" ixy="0" ixz="0" iyy="0.00001" iyz="0" izz="0.00001"/>
    </inertial>
  </link>
  <joint name="f4_palm_servo_joint" type="fixed">
    <parent link="f4_finger_root"/>
    <child link="f4_finger_palm_servo"/>
    <origin rpy="0.000000 0.000000 0.000000" xyz="0.000000 0.000000 0.000000"/>
  </joint>
  <link name="f4_finger_base">
    <visual>
      <origin rpy="0 0 0" xyz="-0.018630 -0.061720 0.028000"/>
      <geometry>
        <mesh filename="robot_meshes/visual/finger_base_vis.obj"/>
      </geometry>
    </visual>
    <collision>
      <origin rpy="0 0 0" xyz="-0.018630 -0.061720 0.028000"/>
      <geometry>
        <mesh filename="robot_meshes/finger_base_servo_part0.obj"/>
      </geometry>
    </collision>
    <inertial>
      <mass value="0.01"/>
      <inertia ixx="0.00001" ixy="0" ixz="0" iyy="0.00001" iyz="0" izz="0.00001"/>
    </inertial>
  </link>
  <joint name="f4_finger_palm_joint" type="revolute">
    <parent link="f4_finger_palm_servo"/>
    <child link="f4_finger_base"/>
    <origin rpy="0.000000 0.000000 0.000000" xyz="0.018630 0.061720 -0.028000"/>
    <axis xyz="0.000000 0.000000 1.000000"/>
    <limit effort="10.0" lower="-0.698000" upper="0.698000" velocity="1.0"/>
    <dynamics damping="0.1" friction="0.01"/>
  </joint>
  <link name="f4_finger_base_lever">
    <visual>
      <origin rpy="0 0 0" xyz="-0.035720 -0.062150 0.032640"/>
      <geometry>
        <mesh filename="robot_meshes/visual/finger_base_lever_vis.obj"/>
      </geometry>
    </visual>
    <collision>
      <origin rpy="0 0 0" xyz="-0.035720 -0.062150 0.032640"/>
      <geometry>
        <mesh filename="robot_meshes/finger_base_lever_part0.obj"/>
      </geometry>
    </collision>
    <collision>
      <origin rpy="0 0 0" xyz="-0.035720 -0.062150 0.032640"/>
      <geometry>
        <mesh filename="robot_meshes/finger_base_lever_part1.obj"/>
      </geometry>
    </collision>
    <collision>
      <origin rpy="0 0 0" xyz="-0.035720 -0.062150 0.032640"/>
      <geometry>
        <mesh filename="robot_meshes/finger_base_lever_part2.obj"/>
      </geometry>
    </collision>
    <visual>
      <origin rpy="0 0 0" xyz="-0.035720 -0.062150 0.032640"/>
      <geometry>
        <mesh filename="robot_meshes/visual/finger_grammar1_vis.obj"/>
      </geometry>
    </visual>
    <collision>
      <origin rpy="0 0 0" xyz="-0.035720 -0.062150 0.032640"/>
      <geometry>
        <mesh filename="robot_meshes/finger_grammar1_part0.obj"/>
      </geometry>
    </collision>
    <inertial>
      <mass value="0.015"/>
      <inertia ixx="0.000015" ixy="0" ixz="0" iyy="0.000015" iyz="0" izz="0.000015"/>
    </inertial>
  </link>
  <joint name="f4_finger_base_joint" type="revolute">
    <parent link="f4_finger_base"/>
    <child link="f4_finger_base_lever"/>
    <origin rpy="0.000000 0.000000 0.000000" xyz="0.017090 0.000430 -0.004640"/>
    <axis xyz="-0.999419 -0.034078 0.000000"/>
    <limit effort="10.0" lower="0.000000" upper="1.570800" velocity="1.0"/>
    <dynamics damping="0.1" friction="0.01"/>
  </joint>
  <link name="f4_finger_middle">
    <visual>
      <origin rpy="0 0 0" xyz="-0.035720 -0.062150 0.032640"/>
      <geometry>
        <mesh filename="robot_meshes/visual/finger_middle_vis.obj"/>
      </geometry>
    </visual>
    <collision>
      <origin rpy="0 0 0" xyz="-0.035720 -0.062150 0.032640"/>
      <geometry>
        <mesh filename="robot_meshes/finger_middle_servo_part0.obj"/>
      </geometry>
    </collision>
    <inertial>
      <mass value="0.01"/>
      <inertia ixx="0.00001" ixy="0" ixz="0" iyy="0.00001" iyz="0" izz="0.00001"/>
    </inertial>
  </link>
  <joint name="f4_middle_joint" type="fixed">
    <parent link="f4_finger_base_lever"/>
    <child link="f4_finger_middle"/>
    <origin rpy="0.000000 0.000000 0.000000" xyz="0.000000 0.000000 0.000000"/>
  </joint>
  <link name="f4_finger_middle_lever">
    <visual>
      <origin rpy="0 0 0" xyz="-0.034570 -0.093620 0.033780"/>
      <geometry>
        <mesh filename="robot_meshes/visual/finger_middle_lever_vis.obj"/>
      </geometry>
    </visual>
    <collision>
      <origin rpy="0 0 0" xyz="-0.034570 -0.093620 0.033780"/>
      <geometry>
        <mesh filename="robot_meshes/finger_middle_lever_part0.obj"/>
      </geometry>
    </collision>
    <collision>
      <origin rpy="0 0 0" xyz="-0.034570 -0.093620 0.033780"/>
      <geometry>
        <mesh filename="robot_meshes/finger_middle_lever_part1.obj"/>
      </geometry>
    </collision>
    <collision>
      <origin rpy="0 0 0" xyz="-0.034570 -0.093620 0.033780"/>
      <geometry>
        <mesh filename="robot_meshes/finger_middle_lever_part2.obj"/>
      </geometry>
    </collision>
    <visual>
      <origin rpy="0 0 0" xyz="-0.034570 -0.093620 0.033780"/>
      <geometry>
        <mesh filename="robot_meshes/visual/finger_grammar2_vis.obj"/>
      </geometry>
    </visual>
    <collision>
      <origin rpy="0 0 0" xyz="-0.034570 -0.093620 0.033780"/>
      <geometry>
        <mesh filename="robot_meshes/finger_grammar2_part0.obj"/>
      </geometry>
    </collision>
    <inertial>
      <mass value="0.015"/>
      <inertia ixx="0.000015" ixy="0" ixz="0" iyy="0.000015" iyz="0" izz="0.000015"/>
    </inertial>
  </link>
  <joint name="f4_finger_middle_joint" type="revolute">
    <parent link="f4_finger_middle"/>
    <child link="f4_finger_middle_lever"/>
    <origin rpy="0.000000 0.000000 0.000000" xyz="-0.001150 0.031470 -0.001140"/>
    <axis xyz="-0.999419 -0.034078 0.000000"/>
    <limit effort="10.0" lower="0.000000" upper="1.570800" velocity="1.0"/>
    <dynamics damping="0.1" friction="0.01"/>
  </joint>
  <link name="f4_finger_end">
    <visual>
      <origin rpy="0 0 0" xyz="-0.034570 -0.093620 0.033780"/>
      <geometry>
        <mesh filename="robot_meshes/visual/finger_end_vis.obj"/>
      </geometry>
    </visual>
    <collision>
      <origin rpy="0 0 0" xyz="-0.034570 -0.093620 0.033780"/>
      <geometry>
        <mesh filename="robot_meshes/finger_end_servo_part0.obj"/>
      </geometry>
    </collision>
    <inertial>
      <mass value="0.01"/>
      <inertia ixx="0.00001" ixy="0" ixz="0" iyy="0.00001" iyz="0" izz="0.00001"/>
    </inertial>
  </link>
  <joint name="f4_end_joint" type="fixed">
    <parent link="f4_finger_middle_lever"/>
    <child link="f4_finger_end"/>
    <origin rpy="0.000000 0.000000 0.000000" xyz="0.000000 0.000000 0.000000"/>
  </joint>
  <link name="f4_finger_end_lever">
    <visual>
      <origin rpy="0 0 0" xyz="-0.033530 -0.125100 0.034780"/>
      <geometry>
        <mesh filename="robot_meshes/visual/finger_end_lever_vis.obj"/>
      </geometry>
    </visual>
    <collision>
      <origin rpy="0 0 0" xyz="-0.033530 -0.125100 0.034780"/>
      <geometry>
        <mesh filename="robot_meshes/finger_end_lever_part0.obj"/>
      </geometry>
    </collision>
    <collision>
      <origin rpy="0 0 0" xyz="-0.033530 -0.125100 0.034780"/>
      <geometry>
        <mesh filename="robot_meshes/finger_end_lever_part1.obj"/>
      </geometry>
    </collision>
    <collision>
      <origin rpy="0 0 0" xyz="-0.033530 -0.125100 0.034780"/>
      <geometry>
        <mesh filename="robot_meshes/finger_end_lever_part2.obj"/>
      </geometry>
    </collision>
    <collision>
      <origin rpy="0 0 0" xyz="-0.033530 -0.125100 0.034780"/>
      <geometry>
        <mesh filename="robot_meshes/finger_end_lever_part3.obj"/>
      </geometry>
    </collision>
    <inertial>
      <mass value="0.01"/>
      <inertia ixx="0.00001" ixy="0" ixz="0" iyy="0.00001" iyz="0" izz="0.00001"/>
    </inertial>
  </link>
  <joint name="f4_finger_end_joint" type="revolute">
    <parent link="f4_finger_end"/>
    <child link="f4_finger_end_lever"/>
    <origin rpy="0.000000 0.000000 0.000000" xyz="-0.001040 0.031480 -0.001000"/>
    <axis xyz="-0.999419 -0.034088 0.000000"/>
    <limit effort="10.0" lower="0.000000" upper="1.570800" velocity="1.0"/>
    <dynamics damping="0.1" friction="0.01"/>
  </joint>
  <link name="f4_finger_tip">
    <visual>
      <origin rpy="0 0 0" xyz="-0.033530 -0.125100 0.034780"/>
      <geometry>
        <mesh filename="robot_meshes/visual/finger_tip_vis.obj"/>
      </geometry>
    </visual>
    <collision>
      <origin rpy="0 0 0" xyz="-0.033530 -0.125100 0.034780"/>
      <geometry>
        <mesh filename="robot_meshes/finger_tip_part0.obj"/>
      </geometry>
    </collision>
    <collision>
      <origin rpy="0 0 0" xyz="-0.033530 -0.125100 0.034780"/>
      <geometry>
        <mesh filename="robot_meshes/finger_tip_part1.obj"/>
      </geometry>
    </collision>
    <inertial>
      <mass value="0.005"/>
      <inertia ixx="0.000001" ixy="0" ixz="0" iyy="0.000001" iyz="0" izz="0.000001"/>
    </inertial>
  </link>
  <joint name="f4_tip_joint" type="fixed">
    <parent link="f4_finger_end_lever"/>
    <child link="f4_finger_tip"/>
    <origin rpy="0.000000 0.000000 0.000000" xyz="0.000000 0.000000 0.000000"/>
  </joint>
  <link name="f5_finger_root">
    <inertial>
      <mass value="0.001"/>
      <inertia ixx="0.000001" ixy="0" ixz="0" iyy="0.000001" iyz="0" izz="0.000001"/>
    </inertial>
  </link>
  <joint name="f5_root_joint" type="fixed">
    <parent link="palm"/>
    <child link="f5_finger_root"/>
    <origin rpy="0.000000 0.000000 -2.656200" xyz="0.059325 -0.005386 0.000000"/>
  </joint>
  <link name="f5_finger_palm_servo">
    <visual>
      <geometry>
        <mesh filename="robot_meshes/visual/finger_palm_servo_vis.obj"/>
      </geometry>
    </visual>
    <collision>
      <geometry>
        <mesh filename="robot_meshes/finger_palm_servo_part0.obj"/>
      </geometry>
    </collision>
    <inertial>
      <mass value="0.01"/>
      <inertia ixx="0.00001" ixy="0" ixz="0" iyy="0.00001" iyz="0" izz="0.00001"/>
    </inertial>
  </link>
  <joint name="f5_palm_servo_joint" type="fixed">
    <parent link="f5_finger_root"/>
    <child link="f5_finger_palm_servo"/>
    <origin rpy="0.000000 0.000000 0.000000" xyz="0.000000 0.000000 0.000000"/>
  </joint>
  <link name="f5_finger_base">
    <visual>
      <origin rpy="0 0 0" xyz="-0.018630 -0.061720 0.028000"/>
      <geometry>
        <mesh filename="robot_meshes/visual/finger_base_vis.obj"/>
      </geometry>
    </visual>
    <collision>
      <origin rpy="0 0 0" xyz="-0.018630 -0.061720 0.028000"/>
      <geometry>
        <mesh filename="robot_meshes/finger_base_servo_part0.obj"/>
      </geometry>
    </collision>
    <inertial>
      <mass value="0.01"/>
      <inertia ixx="0.00001" ixy="0" ixz="0" iyy="0.00001" iyz="0" izz="0.00001"/>
    </inertial>
  </link>
  <joint name="f5_finger_palm_joint" type="revolute">
    <parent link="f5_finger_palm_servo"/>
    <child link="f5_finger_base"/>
    <origin rpy="0.000000 0.000000 0.000000" xyz="0.018630 0.061720 -0.028000"/>
    <axis xyz="0.000000 0.000000 1.000000"/>
    <limit effort="10.0" lower="-0.698000" upper="0.698000" velocity="1.0"/>
    <dynamics damping="0.1" friction="0.01"/>
  </joint>
  <link name="f5_finger_base_lever">
    <visual>
      <origin rpy="0 0 0" xyz="-0.035720 -0.062150 0.032640"/>
      <geometry>
        <mesh filename="robot_meshes/visual/finger_base_lever_vis.obj"/>
      </geometry>
    </visual>
    <collision>
      <origin rpy="0 0 0" xyz="-0.035720 -0.062150 0.032640"/>
      <geometry>
        <mesh filename="robot_meshes/finger_base_lever_part0.obj"/>
      </geometry>
    </collision>
    <collision>
      <origin rpy="0 0 0" xyz="-0.035720 -0.062150 0.032640"/>
      <geometry>
        <mesh filename="robot_meshes/finger_base_lever_part1.obj"/>
      </geometry>
    </collision>
    <collision>
      <origin rpy="0 0 0" xyz="-0.035720 -0.062150 0.032640"/>
      <geometry>
        <mesh filename="robot_meshes/finger_base_lever_part2.obj"/>
      </geometry>
    </collision>
    <visual>
      <origin rpy="0 0 0" xyz="-0.035720 -0.062150 0.032640"/>
      <geometry>
        <mesh filename="robot_meshes/visual/finger_grammar1_vis.obj"/>
      </geometry>
    </visual>
    <collision>
      <origin rpy="0 0 0" xyz="-0.035720 -0.062150 0.032640"/>
      <geometry>
        <mesh filename="robot_meshes/finger_grammar1_part0.obj"/>
      </geometry>
    </collision>
    <inertial>
      <mass value="0.015"/>
      <inertia ixx="0.000015" ixy="0" ixz="0" iyy="0.000015" iyz="0" izz="0.000015"/>
    </inertial>
  </link>
  <joint name="f5_finger_base_joint" type="revolute">
    <parent link="f5_finger_base"/>
    <child link="f5_finger_base_lever"/>
    <origin rpy="0.000000 0.000000 0.000000" xyz="0.017090 0.000430 -0.004640"/>
    <axis xyz="-0.999419 -0.034078 0.000000"/>
    <limit effort="10.0" lower="0.000000" upper="1.570800" velocity="1.0"/>
    <dynamics damping="0.1" friction="0.01"/>
  </joint>
  <link name="f5_finger_middle">
    <visual>
      <origin rpy="0 0 0" xyz="-0.035720 -0.062150 0.032640"/>
      <geometry>
        <mesh filename="robot_meshes/visual/finger_middle_vis.obj"/>
      </geometry>
    </visual>
    <collision>
      <origin rpy="0 0 0" xyz="-0.035720 -0.062150 0.032640"/>
      <geometry>
        <mesh filename="robot_meshes/finger_middle_servo_part0.obj"/>
      </geometry>
    </collision>
    <inertial>
      <mass value="0.01"/>
      <inertia ixx="0.00001" ixy="0" ixz="0" iyy="0.00001" iyz="0" izz="0.00001"/>
    </inertial>
  </link>
  <joint name="f5_middle_joint" type="fixed">
    <parent link="f5_finger_base_lever"/>
    <child link="f5_finger_middle"/>
    <origin rpy="0.000000 0.000000 0.000000" xyz="0.000000 0.000000 0.000000"/>
  </joint>
  <link name="f5_finger_middle_lever">
    <visual>
      <origin rpy="0 0 0" xyz="-0.034570 -0.093620 0.033780"/>
      <geometry>
        <mesh filename="robot_meshes/visual/finger_middle_lever_vis.obj"/>
      </geometry>
    </visual>
    <collision>
      <origin rpy="0 0 0" xyz="-0.034570 -0.093620 0.033780"/>
      <geometry>
        <mesh filename="robot_meshes/finger_middle_lever_part0.obj"/>
      </geometry>
    </collision>
    <collision>
      <origin rpy="0 0 0" xyz="-0.034570 -0.093620 0.033780"/>
      <geometry>
        <mesh filename="robot_meshes/finger_middle_lever_part1.obj"/>
      </geometry>
    </collision>
    <collision>
      <origin rpy="0 0 0" xyz="-0.034570 -0.093620 0.033780"/>
      <geometry>
        <mesh filename="robot_meshes/finger_middle_lever_part2.obj"/>
      </geometry>
    </collision>
    <visual>
      <origin rpy="0 0 0" xyz="-0.034570 -0.093620 0.033780"/>
      <geometry>
        <mesh filename="robot_meshes/visual/finger_grammar2_vis.obj"/>
      </geometry>
    </visual>
    <collision>
      <origin rpy="0 0 0" xyz="-0.034570 -0.093620 0.033780"/>
      <geometry>
        <mesh filename="robot_meshes/finger_grammar2_part0.obj"/>
      </geometry>
    </collision>
    <inertial>
      <mass value="0.015"/>
      <inertia ixx="0.000015" ixy="0" ixz="0" iyy="0.000015" iyz="0" izz="0.000015"/>
    </inertial>
  </link>
  <joint name="f5_finger_middle_joint" type="revolute">
    <parent link="f5_finger_middle"/>
    <child link="f5_finger_middle_lever"/>
    <origin rpy="0.000000 0.000000 0.000000" xyz="-0.001150 0.031470 -0.001140"/>
    <axis xyz="-0.999419 -0.034078 0.000000"/>
    <limit effort="10.0" lower="0.000000" upper="1.570800" velocity="1.0"/>
    <dynamics damping="0.1" friction="0.01"/>
  </joint>
  <link name="f5_finger_end">
    <visual>
      <origin rpy="0 0 0" xyz="-0.034570 -0.093620 0.033780"/>
      <geometry>
        <mesh filename="robot_meshes/visual/finger_end_vis.obj"/>
      </geometry>
    </visual>
    <collision>
      <origin rpy="0 0 0" xyz="-0.034570 -0.093620 0.033780"/>
      <geometry>
        <mesh filename="robot_meshes/finger_end_servo_part0.obj"/>
      </geometry>
    </collision>
    <inertial>
      <mass value="0.01"/>
      <inertia ixx="0.00001" ixy="0" ixz="0" iyy="0.00001" iyz="0" izz="0.00001"/>
    </inertial>
  </link>
  <joint name="f5_end_joint" type="fixed">
    <parent link="f5_finger_middle_lever"/>
    <child link="f5_finger_end"/>
    <origin rpy="0.000000 0.000000 0.000000" xyz="0.000000 0.000000 0.000000"/>
  </joint>
  <link name="f5_finger_end_lever">
    <visual>
      <origin rpy="0 0 0" xyz="-0.033530 -0.125100 0.034780"/>
      <geometry>
        <mesh filename="robot_meshes/visual/finger_end_lever_vis.obj"/>
      </geometry>
    </visual>
    <collision>
      <origin rpy="0 0 0" xyz="-0.033530 -0.125100 0.034780"/>
      <geometry>
        <mesh filename="robot_meshes/finger_end_lever_part0.obj"/>
      </geometry>
    </collision>
    <collision>
      <origin rpy="0 0 0" xyz="-0.033530 -0.125100 0.034780"/>
      <geometry>
        <mesh filename="robot_meshes/finger_end_lever_part1.obj"/>
      </geometry>
    </collision>
    <collision>
      <origin rpy="0 0 0" xyz="-0.033530 -0.125100 0.034780"/>
      <geometry>
        <mesh filename="robot_meshes/finger_end_lever_part2.obj"/>
      </geometry>
    </collision>
    <collision>
      <origin rpy="0 0 0" xyz="-0.033530 -0.125100 0.034780"/>
      <geometry>
        <mesh filename="robot_meshes/finger_end_lever_part3.obj"/>
      </geometry>
    </collision>
    <inertial>
      <mass value="0.01"/>
      <inertia ixx="0.00001" ixy="0" ixz="0" iyy="0.00001" iyz="0" izz="0.00001"/>
    </inertial>
  </link>
  <joint name="f5_finger_end_joint" type="revolute">
    <parent link="f5_finger_end"/>
    <child link="f5_finger_end_lever"/>
    <origin rpy="0.000000 0.000000 0.000000" xyz="-0.001040 0.031480 -0.001000"/>
    <axis xyz="-0.999419 -0.034088 0.000000"/>
    <limit effort="10.0" lower="0.000000" upper="1.570800" velocity="1.0"/>
    <dynamics damping="0.1" friction="0.01"/>
  </joint>
  <link name="f5_finger_tip">
    <visual>
      <origin rpy="0 0 0" xyz="-0.033530 -0.125100 0.034780"/>
      <geometry>
        <mesh filename="robot_meshes/visual/finger_tip_vis.obj"/>
      </geometry>
    </visual>
    <collision>
      <origin rpy="0 0 0" xyz="-0.033530 -0.125100 0.034780"/>
      <geometry>
        <mesh filename="robot_meshes/finger_tip_part0.obj"/>
      </geometry>
    </collision>
    <collision>
      <origin rpy="0 0 0" xyz="-0.033530 -0.125100 0.034780"/>
      <geometry>
        <mesh filename="robot_meshes/finger_tip_part1.obj"/>
      </geometry>
    </collision>
    <inertial>
      <mass value="0.005"/>
      <inertia ixx="0.000001" ixy="0" ixz="0" iyy="0.000001" iyz="0" izz="0.000001"/>
    </inertial>
  </link>
  <joint name="f5_tip_joint" type="fixed">
    <parent link="f5_finger_end_lever"/>
    <child link="f5_finger_tip"/>
    <origin rpy="0.000000 0.000000 0.000000" xyz="0.000000 0.000000 0.000000"/>
  </joint>
</robot>

