<?xml version="1.0" encoding="utf-8"?>
<robot xmlns:xacro="http://www.ros.org/wiki/xacro">
  <!--Auto-converted from lego_finger.xml
Grammar stacks: grammar1=1, grammar2=1
Joint positions: {'palm': (0.01863, 0.06172, -0.028), 'base': (0.03572, 0.06215, -0.03264), 'middle': (0.03457, 0.09362, -0.03378), 'end': (0.03353, 0.1251, -0.03478)}-->
  <xacro:macro name="finger" params="prefix parent *origin">
    <link name="${prefix}finger_root">
      <inertial>
        <mass value="0.001"/>
        <inertia ixx="0.000001" ixy="0" ixz="0" iyy="0.000001" iyz="0" izz="0.000001"/>
      </inertial>
    </link>
    <joint name="${prefix}root_joint" type="fixed">
      <parent link="${parent}"/>
      <child link="${prefix}finger_root"/>
      <xacro:insert_block name="origin"/>
    </joint>
    <link name="${prefix}finger_palm_servo">
      <visual>
        <geometry>
          <mesh filename="robot_meshes/visual/finger_palm_servo_vis.obj"/>
        </geometry>
      </visual>
      <collision>
        <geometry>
          <mesh filename="robot_meshes/finger_palm_servo_part0.obj"/>
        </geometry>
      </collision>
      <inertial>
        <mass value="0.01"/>
        <inertia ixx="0.00001" ixy="0" ixz="0" iyy="0.00001" iyz="0" izz="0.00001"/>
      </inertial>
    </link>
    <joint name="${prefix}palm_servo_joint" type="fixed">
      <parent link="${prefix}finger_root"/>
      <child link="${prefix}finger_palm_servo"/>
      <origin xyz="0.000000 0.000000 0.000000" rpy="0.000000 0.000000 0.000000"/>
    </joint>
    <link name="${prefix}finger_base">
      <visual>
        <origin xyz="-0.018630 -0.061720 0.028000" rpy="0 0 0"/>
        <geometry>
          <mesh filename="robot_meshes/visual/finger_base_vis.obj"/>
        </geometry>
      </visual>
      <collision>
        <origin xyz="-0.018630 -0.061720 0.028000" rpy="0 0 0"/>
        <geometry>
          <mesh filename="robot_meshes/finger_base_servo_part0.obj"/>
        </geometry>
      </collision>
      <inertial>
        <mass value="0.01"/>
        <inertia ixx="0.00001" ixy="0" ixz="0" iyy="0.00001" iyz="0" izz="0.00001"/>
      </inertial>
    </link>
    <joint name="${prefix}finger_palm_joint" type="revolute">
      <parent link="${prefix}finger_palm_servo"/>
      <child link="${prefix}finger_base"/>
      <origin xyz="0.018630 0.061720 -0.028000" rpy="0.000000 0.000000 0.000000"/>
      <axis xyz="0.000000 0.000000 1.000000"/>
      <limit lower="-0.698000" upper="0.698000" effort="10.0" velocity="1.0"/>
      <dynamics damping="0.1" friction="0.01"/>
    </joint>
    <link name="${prefix}finger_base_lever">
      <visual>
        <origin xyz="-0.035720 -0.062150 0.032640" rpy="0 0 0"/>
        <geometry>
          <mesh filename="robot_meshes/visual/finger_base_lever_vis.obj"/>
        </geometry>
      </visual>
      <collision>
        <origin xyz="-0.035720 -0.062150 0.032640" rpy="0 0 0"/>
        <geometry>
          <mesh filename="robot_meshes/finger_base_lever_part0.obj"/>
        </geometry>
      </collision>
      <collision>
        <origin xyz="-0.035720 -0.062150 0.032640" rpy="0 0 0"/>
        <geometry>
          <mesh filename="robot_meshes/finger_base_lever_part1.obj"/>
        </geometry>
      </collision>
      <collision>
        <origin xyz="-0.035720 -0.062150 0.032640" rpy="0 0 0"/>
        <geometry>
          <mesh filename="robot_meshes/finger_base_lever_part2.obj"/>
        </geometry>
      </collision>
      <visual>
        <origin xyz="-0.035720 -0.062150 0.032640" rpy="0 0 0"/>
        <geometry>
          <mesh filename="robot_meshes/visual/finger_grammar1_vis.obj"/>
        </geometry>
      </visual>
      <collision>
        <origin xyz="-0.035720 -0.062150 0.032640" rpy="0 0 0"/>
        <geometry>
          <mesh filename="robot_meshes/finger_grammar1_part0.obj"/>
        </geometry>
      </collision>
      <inertial>
        <mass value="0.015"/>
        <inertia ixx="0.000015" ixy="0" ixz="0" iyy="0.000015" iyz="0" izz="0.000015"/>
      </inertial>
    </link>
    <joint name="${prefix}finger_base_joint" type="revolute">
      <parent link="${prefix}finger_base"/>
      <child link="${prefix}finger_base_lever"/>
      <origin xyz="0.017090 0.000430 -0.004640" rpy="0.000000 0.000000 0.000000"/>
      <axis xyz="-0.999419 -0.034078 0.000000"/>
      <limit lower="0.000000" upper="1.570800" effort="10.0" velocity="1.0"/>
      <dynamics damping="0.1" friction="0.01"/>
    </joint>
    <link name="${prefix}finger_middle">
      <visual>
        <origin xyz="-0.035720 -0.062150 0.032640" rpy="0 0 0"/>
        <geometry>
          <mesh filename="robot_meshes/visual/finger_middle_vis.obj"/>
        </geometry>
      </visual>
      <collision>
        <origin xyz="-0.035720 -0.062150 0.032640" rpy="0 0 0"/>
        <geometry>
          <mesh filename="robot_meshes/finger_middle_servo_part0.obj"/>
        </geometry>
      </collision>
      <inertial>
        <mass value="0.01"/>
        <inertia ixx="0.00001" ixy="0" ixz="0" iyy="0.00001" iyz="0" izz="0.00001"/>
      </inertial>
    </link>
    <joint name="${prefix}middle_joint" type="fixed">
      <parent link="${prefix}finger_base_lever"/>
      <child link="${prefix}finger_middle"/>
      <origin xyz="0.000000 0.000000 0.000000" rpy="0.000000 0.000000 0.000000"/>
    </joint>
    <link name="${prefix}finger_middle_lever">
      <visual>
        <origin xyz="-0.034570 -0.093620 0.033780" rpy="0 0 0"/>
        <geometry>
          <mesh filename="robot_meshes/visual/finger_middle_lever_vis.obj"/>
        </geometry>
      </visual>
      <collision>
        <origin xyz="-0.034570 -0.093620 0.033780" rpy="0 0 0"/>
        <geometry>
          <mesh filename="robot_meshes/finger_middle_lever_part0.obj"/>
        </geometry>
      </collision>
      <collision>
        <origin xyz="-0.034570 -0.093620 0.033780" rpy="0 0 0"/>
        <geometry>
          <mesh filename="robot_meshes/finger_middle_lever_part1.obj"/>
        </geometry>
      </collision>
      <collision>
        <origin xyz="-0.034570 -0.093620 0.033780" rpy="0 0 0"/>
        <geometry>
          <mesh filename="robot_meshes/finger_middle_lever_part2.obj"/>
        </geometry>
      </collision>
      <visual>
        <origin xyz="-0.034570 -0.093620 0.033780" rpy="0 0 0"/>
        <geometry>
          <mesh filename="robot_meshes/visual/finger_grammar2_vis.obj"/>
        </geometry>
      </visual>
      <collision>
        <origin xyz="-0.034570 -0.093620 0.033780" rpy="0 0 0"/>
        <geometry>
          <mesh filename="robot_meshes/finger_grammar2_part0.obj"/>
        </geometry>
      </collision>
      <inertial>
        <mass value="0.015"/>
        <inertia ixx="0.000015" ixy="0" ixz="0" iyy="0.000015" iyz="0" izz="0.000015"/>
      </inertial>
    </link>
    <joint name="${prefix}finger_middle_joint" type="revolute">
      <parent link="${prefix}finger_middle"/>
      <child link="${prefix}finger_middle_lever"/>
      <origin xyz="-0.001150 0.031470 -0.001140" rpy="0.000000 0.000000 0.000000"/>
      <axis xyz="-0.999419 -0.034078 0.000000"/>
      <limit lower="0.000000" upper="1.570800" effort="10.0" velocity="1.0"/>
      <dynamics damping="0.1" friction="0.01"/>
    </joint>
    <link name="${prefix}finger_end">
      <visual>
        <origin xyz="-0.034570 -0.093620 0.033780" rpy="0 0 0"/>
        <geometry>
          <mesh filename="robot_meshes/visual/finger_end_vis.obj"/>
        </geometry>
      </visual>
      <collision>
        <origin xyz="-0.034570 -0.093620 0.033780" rpy="0 0 0"/>
        <geometry>
          <mesh filename="robot_meshes/finger_end_servo_part0.obj"/>
        </geometry>
      </collision>
      <inertial>
        <mass value="0.01"/>
        <inertia ixx="0.00001" ixy="0" ixz="0" iyy="0.00001" iyz="0" izz="0.00001"/>
      </inertial>
    </link>
    <joint name="${prefix}end_joint" type="fixed">
      <parent link="${prefix}finger_middle_lever"/>
      <child link="${prefix}finger_end"/>
      <origin xyz="0.000000 0.000000 0.000000" rpy="0.000000 0.000000 0.000000"/>
    </joint>
    <link name="${prefix}finger_end_lever">
      <visual>
        <origin xyz="-0.033530 -0.125100 0.034780" rpy="0 0 0"/>
        <geometry>
          <mesh filename="robot_meshes/visual/finger_end_lever_vis.obj"/>
        </geometry>
      </visual>
      <collision>
        <origin xyz="-0.033530 -0.125100 0.034780" rpy="0 0 0"/>
        <geometry>
          <mesh filename="robot_meshes/finger_end_lever_part0.obj"/>
        </geometry>
      </collision>
      <collision>
        <origin xyz="-0.033530 -0.125100 0.034780" rpy="0 0 0"/>
        <geometry>
          <mesh filename="robot_meshes/finger_end_lever_part1.obj"/>
        </geometry>
      </collision>
      <collision>
        <origin xyz="-0.033530 -0.125100 0.034780" rpy="0 0 0"/>
        <geometry>
          <mesh filename="robot_meshes/finger_end_lever_part2.obj"/>
        </geometry>
      </collision>
      <collision>
        <origin xyz="-0.033530 -0.125100 0.034780" rpy="0 0 0"/>
        <geometry>
          <mesh filename="robot_meshes/finger_end_lever_part3.obj"/>
        </geometry>
      </collision>
      <inertial>
        <mass value="0.01"/>
        <inertia ixx="0.00001" ixy="0" ixz="0" iyy="0.00001" iyz="0" izz="0.00001"/>
      </inertial>
    </link>
    <joint name="${prefix}finger_end_joint" type="revolute">
      <parent link="${prefix}finger_end"/>
      <child link="${prefix}finger_end_lever"/>
      <origin xyz="-0.001040 0.031480 -0.001000" rpy="0.000000 0.000000 0.000000"/>
      <axis xyz="-0.999419 -0.034088 0.000000"/>
      <limit lower="0.000000" upper="1.570800" effort="10.0" velocity="1.0"/>
      <dynamics damping="0.1" friction="0.01"/>
    </joint>
    <link name="${prefix}finger_tip">
      <visual>
        <origin xyz="-0.033530 -0.125100 0.034780" rpy="0 0 0"/>
        <geometry>
          <mesh filename="robot_meshes/visual/finger_tip_vis.obj"/>
        </geometry>
      </visual>
      <collision>
        <origin xyz="-0.033530 -0.125100 0.034780" rpy="0 0 0"/>
        <geometry>
          <mesh filename="robot_meshes/finger_tip_part0.obj"/>
        </geometry>
      </collision>
      <collision>
        <origin xyz="-0.033530 -0.125100 0.034780" rpy="0 0 0"/>
        <geometry>
          <mesh filename="robot_meshes/finger_tip_part1.obj"/>
        </geometry>
      </collision>
      <inertial>
        <mass value="0.005"/>
        <inertia ixx="0.000001" ixy="0" ixz="0" iyy="0.000001" iyz="0" izz="0.000001"/>
      </inertial>
    </link>
    <joint name="${prefix}tip_joint" type="fixed">
      <parent link="${prefix}finger_end_lever"/>
      <child link="${prefix}finger_tip"/>
      <origin xyz="0.000000 0.000000 0.000000" rpy="0.000000 0.000000 0.000000"/>
    </joint>
  </xacro:macro>
</robot>